<mujoco model="pipette_liquid_transfer_demo">
  <compiler angle="radian" autolimits="true" meshdir="/data/tianang/projects/AutoBio/autobio/assets/" />
  <option timestep="0.002" integrator="implicitfast" cone="elliptic" gravity="0 0 -9.81" />

  <visual>
    <headlight diffuse="0.65 0.65 0.65" ambient="0.35 0.35 0.35" specular="0.1 0.1 0.1" />
    <global azimuth="135" elevation="-18" offwidth="1280" offheight="720" />
  </visual>

  <asset>
    <texture name="grid" type="2d" builtin="checker" width="512" height="512" rgb1="0.25 0.25 0.25" rgb2="0.32 0.32 0.32" />
    <material name="floor_grid" texture="grid" texrepeat="4 4" reflectance="0.08" />

    <mesh name="pipette_connector_visual" file="tool/pipette/connector_visual.obj" scale="0.1 0.1 0.1" />
    <mesh name="pipette_knob_visual" file="tool/pipette/knob_visual.obj" scale="0.1 0.1 0.1" />
    <mesh name="pipette_tube_visual" file="tool/pipette/tube_visual.obj" scale="0.1 0.1 0.1" />
    <mesh name="pipette_tube_collision_0" file="tool/pipette/tube_collision_0.obj" scale="0.1 0.1 0.1" />
    <mesh name="pipette_tube_collision_1" file="tool/pipette/tube_collision_1.obj" scale="0.1 0.1 0.1" />
    <mesh name="pipette_pusher_right1_visual" file="tool/pipette/pusher_right1_visual.obj" scale="0.1 0.1 0.1" />
    <mesh name="pipette_pusher_right1_collision_0" file="tool/pipette/pusher_right1_collision_0.obj" scale="0.1 0.1 0.1" />
    <mesh name="pipette_pusher_right2_visual" file="tool/pipette/pusher_right2_visual.obj" scale="0.1 0.1 0.1" />
    <mesh name="pipette_pusher_right2_collision_0" file="tool/pipette/pusher_right2_collision_0.obj" scale="0.1 0.1 0.1" />
    <mesh name="pipette_body_visual" file="tool/pipette/body_visual.obj" scale="0.1 0.1 0.1" />
    <mesh name="pipette_body_collision_0" file="tool/pipette/body_collision_0.obj" scale="0.1 0.1 0.1" />
    <mesh name="pipette_body_collision_1" file="tool/pipette/body_collision_1.obj" scale="0.1 0.1 0.1" />
    <mesh name="pipette_body_collision_2" file="tool/pipette/body_collision_2.obj" scale="0.1 0.1 0.1" />
    <mesh name="pipette_body_collision_3" file="tool/pipette/body_collision_3.obj" scale="0.1 0.1 0.1" />
    <mesh name="pipette_pusher_mid_visual" file="tool/pipette/pusher_mid_visual.obj" scale="0.1 0.1 0.1" />
    <mesh name="pipette_pusher_right3_visual" file="tool/pipette/pusher_right3_visual.obj" scale="0.1 0.1 0.1" />
    <mesh name="pipette_pusher_right3_collision_0" file="tool/pipette/pusher_right3_collision_0.obj" scale="0.1 0.1 0.1" />
    <mesh name="pipette_pusher_right3_collision_1" file="tool/pipette/pusher_right3_collision_1.obj" scale="0.1 0.1 0.1" />
    <mesh name="pipette_tip_visual" file="container/tip_200ul_vis/visual.obj" scale="0.001 0.001 0.001" />
    <mesh name="pipette_tip_collision_0" file="container/tip_200ul_col/tip_collision_0.obj" scale="0.001 0.001 0.001" />

    <material name="pipette_plastic" rgba="0.8 0.8 0.8 1" />
    <material name="pipette_button" rgba="0.45 0.68 0.95 1" />
    <material name="tip_clear" rgba="1 1 1 0.35" />
    <material name="glass_clear" rgba="0.9 0.97 1 0.22" />
    <material name="liquid_blue" rgba="0.08 0.36 0.95 0.68" />
  </asset>

  <worldbody>
    <light name="key" pos="0.2 -0.5 0.55" dir="-0.2 0.6 -1" diffuse="0.8 0.8 0.8" />
    <geom name="floor" type="plane" size="0.45 0.35 0.02" material="floor_grid" />

    <camera name="liquid_camera" pos="0.20 -0.34 0.21" xyaxes="0.86 0.51 0 -0.18 0.31 0.93" />

    <body name="source_tube" pos="-0.105 0 0">
      <geom name="source_tube_wall" type="cylinder" size="0.009 0.055" pos="0 0 0.061" contype="0" conaffinity="0" group="2" material="glass_clear" />
      <geom name="source_liquid" type="cylinder" size="0.006 0.0001" pos="0 0 0.0961" contype="0" conaffinity="0" group="2" material="liquid_blue" />
    </body>

    <body name="target_well" pos="0.105 0 0">
      <geom name="target_well_wall" type="cylinder" size="0.011 0.022" pos="0 0 0.108" contype="0" conaffinity="0" group="2" material="glass_clear" />
      <geom name="target_liquid" type="cylinder" size="0.0045 0.0001" pos="0 0 0.0961" contype="0" conaffinity="0" group="2" rgba="0.08 0.36 0.95 0" />
    </body>

    <body name="pipette" pos="-0.105 0 0.1534" quat="1 0 0 0">
      <geom type="mesh" contype="0" conaffinity="0" group="2" mesh="pipette_body_visual" material="pipette_plastic" />
      <geom type="mesh" group="3" mesh="pipette_body_collision_0" />
      <geom type="mesh" group="3" mesh="pipette_body_collision_1" />
      <geom type="mesh" group="3" mesh="pipette_body_collision_2" />
      <geom type="mesh" group="3" mesh="pipette_body_collision_3" />
      <geom type="mesh" contype="0" conaffinity="0" group="2" mesh="pipette_tube_visual" material="pipette_plastic" />
      <geom type="mesh" group="3" mesh="pipette_tube_collision_0" />
      <geom type="mesh" group="3" mesh="pipette_tube_collision_1" />
      <geom name="connector_visual" type="mesh" contype="0" conaffinity="0" group="2" mesh="pipette_connector_visual" material="pipette_plastic" />
      <geom name="connector_collision" size="0.00199955 0.004" pos="0 0 -0.004" type="cylinder" conaffinity="5" group="3" />

      <body name="pipette_ejector">
        <joint name="pipette_ejector" pos="0 0 0" axis="0 0 1" type="slide" springref="0.006333333333" stiffness="315.789473684" limited="true" range="-0.0095 0" damping="8" />
        <geom type="mesh" contype="0" conaffinity="0" group="2" mesh="pipette_pusher_right1_visual" material="pipette_button" />
        <geom type="mesh" group="3" mesh="pipette_pusher_right1_collision_0" />
        <geom type="mesh" contype="0" conaffinity="0" group="2" mesh="pipette_pusher_right2_visual" material="pipette_button" />
        <geom type="mesh" group="3" mesh="pipette_pusher_right2_collision_0" />
        <geom type="mesh" contype="0" conaffinity="0" group="2" mesh="pipette_pusher_right3_visual" material="pipette_button" />
        <geom type="mesh" group="3" mesh="pipette_pusher_right3_collision_0" />
        <geom type="mesh" group="3" mesh="pipette_pusher_right3_collision_1" />
      </body>

      <body name="pipette_button">
        <joint name="pipette_button" pos="0 0 0" axis="0 0 1" type="slide" springref="0.04" stiffness="1" limited="true" range="-0.008 0" damping="1" />
        <geom type="mesh" contype="0" conaffinity="0" group="2" mesh="pipette_pusher_mid_visual" material="pipette_plastic" />
        <geom size="0.00502107 0.00485" pos="0 0 0.181306" type="cylinder" group="3" />
        <body name="pipette_knob">
          <joint name="knob" pos="0 0 0" axis="0 0 1" range="-1.5 1.5" damping="1" frictionloss="0.0001" />
          <geom type="mesh" contype="0" conaffinity="0" group="2" mesh="pipette_knob_visual" material="pipette_button" />
          <geom size="0.00869505 0.00225" pos="0 0 0.188406" type="cylinder" group="3" />
        </body>
      </body>

      <body name="pipette_tip" pos="0 0 -0.003" quat="1 0 0 0">
        <geom type="mesh" contype="0" conaffinity="0" group="2" mesh="pipette_tip_visual" material="tip_clear" />
        <geom type="mesh" group="3" mesh="pipette_tip_collision_0" />
        <site name="tip_site" pos="0 0 -0.05" quat="1 0 0 0" type="sphere" group="5" rgba="0.9 0.9 0.9 1" size="0.0008" />

        <geom name="tip_liquid_seg_00" type="cylinder" size="0.00022 0.00072" pos="0 0 -0.0488" contype="0" conaffinity="0" group="2" rgba="0.08 0.36 0.95 0" />
        <geom name="tip_liquid_seg_01" type="cylinder" size="0.00025 0.00072" pos="0 0 -0.0473" contype="0" conaffinity="0" group="2" rgba="0.08 0.36 0.95 0" />
        <geom name="tip_liquid_seg_02" type="cylinder" size="0.00029 0.00072" pos="0 0 -0.0458" contype="0" conaffinity="0" group="2" rgba="0.08 0.36 0.95 0" />
        <geom name="tip_liquid_seg_03" type="cylinder" size="0.00033 0.00072" pos="0 0 -0.0443" contype="0" conaffinity="0" group="2" rgba="0.08 0.36 0.95 0" />
        <geom name="tip_liquid_seg_04" type="cylinder" size="0.00038 0.00072" pos="0 0 -0.0428" contype="0" conaffinity="0" group="2" rgba="0.08 0.36 0.95 0" />
        <geom name="tip_liquid_seg_05" type="cylinder" size="0.00043 0.00072" pos="0 0 -0.0413" contype="0" conaffinity="0" group="2" rgba="0.08 0.36 0.95 0" />
        <geom name="tip_liquid_seg_06" type="cylinder" size="0.00048 0.00072" pos="0 0 -0.0398" contype="0" conaffinity="0" group="2" rgba="0.08 0.36 0.95 0" />
        <geom name="tip_liquid_seg_07" type="cylinder" size="0.00054 0.00072" pos="0 0 -0.0383" contype="0" conaffinity="0" group="2" rgba="0.08 0.36 0.95 0" />
        <geom name="tip_liquid_seg_08" type="cylinder" size="0.00060 0.00072" pos="0 0 -0.0368" contype="0" conaffinity="0" group="2" rgba="0.08 0.36 0.95 0" />
        <geom name="tip_liquid_seg_09" type="cylinder" size="0.00066 0.00072" pos="0 0 -0.0353" contype="0" conaffinity="0" group="2" rgba="0.08 0.36 0.95 0" />
        <geom name="tip_liquid_seg_10" type="cylinder" size="0.00073 0.00072" pos="0 0 -0.0338" contype="0" conaffinity="0" group="2" rgba="0.08 0.36 0.95 0" />
        <geom name="tip_liquid_seg_11" type="cylinder" size="0.00080 0.00072" pos="0 0 -0.0323" contype="0" conaffinity="0" group="2" rgba="0.08 0.36 0.95 0" />
        <geom name="tip_liquid_seg_12" type="cylinder" size="0.00087 0.00072" pos="0 0 -0.0308" contype="0" conaffinity="0" group="2" rgba="0.08 0.36 0.95 0" />
        <geom name="tip_liquid_seg_13" type="cylinder" size="0.00094 0.00072" pos="0 0 -0.0293" contype="0" conaffinity="0" group="2" rgba="0.08 0.36 0.95 0" />
        <geom name="tip_liquid_seg_14" type="cylinder" size="0.00102 0.00072" pos="0 0 -0.0278" contype="0" conaffinity="0" group="2" rgba="0.08 0.36 0.95 0" />
        <geom name="tip_liquid_seg_15" type="cylinder" size="0.00110 0.00072" pos="0 0 -0.0263" contype="0" conaffinity="0" group="2" rgba="0.08 0.36 0.95 0" />
        <geom name="tip_liquid_seg_16" type="cylinder" size="0.00118 0.00072" pos="0 0 -0.0248" contype="0" conaffinity="0" group="2" rgba="0.08 0.36 0.95 0" />
        <geom name="tip_liquid_seg_17" type="cylinder" size="0.00126 0.00072" pos="0 0 -0.0233" contype="0" conaffinity="0" group="2" rgba="0.08 0.36 0.95 0" />
        <geom name="tip_liquid_seg_18" type="cylinder" size="0.00135 0.00072" pos="0 0 -0.0218" contype="0" conaffinity="0" group="2" rgba="0.08 0.36 0.95 0" />
        <geom name="tip_liquid_seg_19" type="cylinder" size="0.00144 0.00072" pos="0 0 -0.0203" contype="0" conaffinity="0" group="2" rgba="0.08 0.36 0.95 0" />
        <geom name="tip_liquid_seg_20" type="cylinder" size="0.00154 0.00072" pos="0 0 -0.0188" contype="0" conaffinity="0" group="2" rgba="0.08 0.36 0.95 0" />
        <geom name="tip_liquid_seg_21" type="cylinder" size="0.00164 0.00072" pos="0 0 -0.0173" contype="0" conaffinity="0" group="2" rgba="0.08 0.36 0.95 0" />
        <geom name="tip_liquid_seg_22" type="cylinder" size="0.00174 0.00072" pos="0 0 -0.0158" contype="0" conaffinity="0" group="2" rgba="0.08 0.36 0.95 0" />
        <geom name="tip_liquid_seg_23" type="cylinder" size="0.00185 0.00072" pos="0 0 -0.0143" contype="0" conaffinity="0" group="2" rgba="0.08 0.36 0.95 0" />
      </body>
    </body>
  </worldbody>

  <contact>
    <exclude body1="pipette" body2="pipette_button" />
    <exclude body1="pipette" body2="pipette_knob" />
    <exclude body1="pipette" body2="pipette_ejector" />
    <exclude body1="pipette" body2="pipette_tip" />
  </contact>

  <actuator>
    <position name="pipette_button_position" joint="pipette_button" ctrlrange="-0.008 0" kp="2500" kv="25" forcerange="-8 8" />
  </actuator>
</mujoco>
